<?xml version="1.0" ?>
<robot name="medibot" xmlns:xacro="http://www.ros.org/wiki/xacro">

<xacro:include filename="$(find medibot_description)/urdf/materials.xacro" />
<xacro:include filename="$(find medibot_description)/urdf/medibot.trans" />
<xacro:include filename="$(find medibot_description)/urdf/medibot.gazebo" />
<link name="base_link">
  <inertial>
    <origin xyz="0.04581707300319793 0.0010479310706408762 0.07330638052099143" rpy="0 0 0"/>
    <mass value="6.358114447165492"/>
    <inertia ixx="0.037035" iyy="0.038312" izz="0.055341" ixy="-0.000504" iyz="-1.1e-05" ixz="-0.00176"/>
  </inertial>
  <visual>
    <origin xyz="0 0 0" rpy="0 0 0"/>
    <geometry>
      <mesh filename="package://medibot_description/meshes/base_link.stl" scale="0.001 0.001 0.001"/>
    </geometry>
    <material name="black"/>
  </visual>
  <collision>
    <origin xyz="0 0 0" rpy="0 0 0"/>
    <geometry>
      <mesh filename="package://medibot_description/meshes/base_link.stl" scale="0.001 0.001 0.001"/>
    </geometry>
  </collision>
</link>

<link name="l_wheel_1">
  <inertial>
    <origin xyz="2.1103228532710293e-07 0.0037429225188824466 7.237266341775239e-15" rpy="0 0 0"/>
    <mass value="0.8943597759780031"/>
    <inertia ixx="0.000733" iyy="0.001393" izz="0.000733" ixy="0.0" iyz="-0.0" ixz="0.0"/>
  </inertial>
  <visual>
    <origin xyz="-0.0 -0.1292 -0.05" rpy="0 0 0"/>
    <geometry>
      <mesh filename="package://medibot_description/meshes/l_wheel_1.stl" scale="0.001 0.001 0.001"/>
    </geometry>
    <material name="plastic_translucent_glossy_gray"/>
  </visual>
  <collision>
    <origin xyz="-0.0 -0.1292 -0.05" rpy="0 0 0"/>
    <geometry>
      <mesh filename="package://medibot_description/meshes/l_wheel_1.stl" scale="0.001 0.001 0.001"/>
    </geometry>
  </collision>
</link>

<link name="r_wheel_1">
  <inertial>
    <origin xyz="2.1103229032957658e-07 -0.003743027969156404 5.044575868140555e-15" rpy="0 0 0"/>
    <mass value="0.8943597759780031"/>
    <inertia ixx="0.000733" iyy="0.001393" izz="0.000733" ixy="0.0" iyz="0.0" ixz="0.0"/>
  </inertial>
  <visual>
    <origin xyz="-0.0 0.1292 -0.05" rpy="0 0 0"/>
    <geometry>
      <mesh filename="package://medibot_description/meshes/r_wheel_1.stl" scale="0.001 0.001 0.001"/>
    </geometry>
    <material name="plastic_translucent_glossy_gray"/>
  </visual>
  <collision>
    <origin xyz="-0.0 0.1292 -0.05" rpy="0 0 0"/>
    <geometry>
      <mesh filename="package://medibot_description/meshes/r_wheel_1.stl" scale="0.001 0.001 0.001"/>
    </geometry>
  </collision>
</link>

<link name="lidar_1">
  <inertial>
    <origin xyz="-0.155 -8.8e-05 -0.1428" rpy="0 0 0"/>
    <mass value="0.0"/>
    <inertia ixx="0.0" iyy="0.0" izz="0.0" ixy="0.0" iyz="0.0" ixz="0.0"/>
  </inertial>
  <visual>
    <origin xyz="-0.155 -8.8e-05 -0.1428" rpy="0 0 0"/>
    <geometry>
      <mesh filename="package://medibot_description/meshes/lidar_1.stl" scale="0.001 0.001 0.001"/>
    </geometry>
    <material name="blue"/>
  </visual>
  <collision>
    <origin xyz="-0.155 -8.8e-05 -0.1428" rpy="0 0 0"/>
    <geometry>
      <mesh filename="package://medibot_description/meshes/lidar_1.stl" scale="0.001 0.001 0.001"/>
    </geometry>
  </collision>
</link>

<joint name="base2left" type="continuous">
  <origin xyz="0.0 0.1292 0.05" rpy="0 0 0"/>
  <parent link="base_link"/>
  <child link="l_wheel_1"/>
  <axis xyz="0.0 1.0 0.0"/>
</joint>

<joint name="base2right" type="continuous">
  <origin xyz="0.0 -0.1292 0.05" rpy="0 0 0"/>
  <parent link="base_link"/>
  <child link="r_wheel_1"/>
  <axis xyz="0.0 1.0 0.0"/>
</joint>

<joint name="base2lidar" type="fixed">
  <origin xyz="0.155 8.8e-05 0.1428" rpy="0 0 0"/>
  <parent link="base_link"/>
  <child link="lidar_1"/>
</joint>

</robot>
